<?xml version="1.0" ?>
<!-- =================================================================================== -->
<!-- |    This document was autogenerated by xacro from mira.urdf.xacro                | -->
<!-- |    EDITING THIS FILE BY HAND IS NOT RECOMMENDED                                 | -->
<!-- =================================================================================== -->
<robot name="mira" xmlns:controller="http://playerstage.sourceforge.net/gazebo/xmlschema/#controller" xmlns:interface="http://playerstage.sourceforge.net/gazebo/xmlschema/#interface" xmlns:sensor="http://playerstage.sourceforge.net/gazebo/xmlschema/#sensor" xmlns:xacro="http://wiki.ros.org/xacro">
  <!-- arm -->
  <!-- Encoder offsets are not included here but set in a separate config file -->
  <material name="blue">
    <color rgba="0 0 0.8 1"/>
  </material>
  <material name="white">
    <color rgba="1 1 1 1"/>
  </material>
  <material name="MelonYellow">
    <color rgba="1.0 0.6 0.0 1.0"/>
  </material>
  <link name="root_link">
		</link>
  <joint name="root_joint" type="fixed">
    <!-- joint1 base_to_right_leg 0.2945 -->
    <origin rpy="0 0 1.5708" xyz="0 0 0.0"/>
    <axis xyz="0 0 1"/>
    <parent link="root_link"/>
    <child link="base_link"/>
  </joint>
  <link name="base_link">
    <!-- link0 -->
    <inertial>
      <mass value="9.02994035"/>
      <origin rpy="0 0 0" xyz="-0.00864914 0.00066084 0.09191042"/>
      <!-- did not chenge inertia values -->
      <inertia ixx="0.04871169" ixy="0.00072792" ixz="-0.00354042" iyy="0.06082174" iyz="0.00036285" izz="0.06803946"/>
    </inertial>
    <visual>
      <origin rpy="0 0 0" xyz="0 0 0"/>
      <geometry>
        <mesh filename="package://mira_description/meshes/mira/Link0.stl"/>
      </geometry>
      <material name="blue"/>
    </visual>
    <collision>
      <origin rpy="0 0 0" xyz="0 0 0"/>
      <geometry>
        <mesh filename="package://mira_description/meshes/collision/Link0.stl"/>
      </geometry>
      <material name="blue"/>
    </collision>
  </link>
  <link name="link1">
    <!-- link1 right_leg-->
    <inertial>
      <mass value="8.81388995"/>
      <origin rpy="0 0 0" xyz="0.00009227 0.01727770 -0.09151695"/>
      <inertia ixx="0.11695855" ixy="-0.00006599" ixz="-0.00007443" iyy="0.09523956" iyz="-0.01391589" izz="0.05142057"/>
    </inertial>
    <visual>
      <origin rpy="0 0 0" xyz="0 0 0"/>
      <geometry>
        <mesh filename="package://mira_description/meshes/mira/Link1.stl"/>
      </geometry>
      <material name="white"/>
    </visual>
    <collision>
      <origin rpy="0 0 0" xyz="0 0 0"/>
      <geometry>
        <mesh filename="package://mira_description/meshes/collision/Link1.stl"/>
      </geometry>
      <material name="white"/>
    </collision>
  </link>
  <joint name="joint1" type="revolute">
    <!-- joint1 base_to_right_leg 0.2945 -->
    <origin rpy="0 0 0" xyz="0 0 0.353"/>
    <axis xyz="0 0 1"/>
    <limit effort="1260" lower="-4.7139" upper="4.7139" velocity="7.60"/>
    <parent link="base_link"/>
    <child link="link1"/>
  </joint>
  <link name="link2">
    <!-- link2 right_base -->
    <inertial>
      <mass value="10.73876455"/>
      <origin rpy="0 0 0" xyz="0.00005095 -0.02980593 0.00384129"/>
      <inertia ixx="0.08469338" ixy="-0.00000976" ixz="0.00000284" iyy="0.04466526" iyz="-0.00106970" izz="0.08929344"/>
    </inertial>
    <visual>
      <origin rpy="0 0 0" xyz="0 0 0"/>
      <geometry>
        <mesh filename="package://mira_description/meshes/mira/Link2.stl"/>
      </geometry>
      <material name="blue"/>
    </visual>
    <collision>
      <origin rpy="0 0 0" xyz="0 0 0"/>
      <geometry>
        <mesh filename="package://mira_description/meshes/collision/Link2.stl"/>
      </geometry>
      <material name="blue"/>
    </collision>
  </link>
  <joint name="joint2" type="revolute">
    <!-- joint2 right_base_joint -->
    <origin rpy="-1.57039 0 0" xyz="-4.13079e-05 -5.3146e-06 -2.13721e-09"/>
    <axis xyz="0 0 1"/>
    <limit effort="710" lower="-2.11" upper="2.11" velocity="7.16"/>
    <safety_controller k_position="100" k_velocity="2" soft_lower_limit="-2.105948851735" soft_upper_limit="2.105948851735"/>
    <dynamics damping="13.0" friction="9.0"/>
    <parent link="link1"/>
    <child link="link2"/>
  </joint>
  <link name="link3">
    <!-- link3 right_front_wheel -->
    <inertial>
      <mass value="7.80048461"/>
      <origin rpy="0 0 0" xyz="0.00000508 -0.01311256 -0.29310398"/>
      <inertia ixx="0.37362453" ixy="-0.00000061" ixz="-0.00001502" iyy="0.36314616" iyz="0.02636093" izz="0.02643739"/>
    </inertial>
    <visual>
      <origin rpy="0 0 0" xyz="0 0 0"/>
      <geometry>
        <mesh filename="package://mira_description/meshes/mira/Link3.stl"/>
      </geometry>
      <material name="white"/>
    </visual>
    <collision>
      <origin rpy="0 0 0" xyz="0 0 0"/>
      <geometry>
        <mesh filename="package://mira_description/meshes/collision/Link3.stl"/>
      </geometry>
      <material name="white"/>
    </collision>
  </link>
  <joint name="joint3" type="revolute">
    <!-- joint3 right_front_wheel_joint -->
    <origin rpy="1.56916 0 0" xyz="7.86969e-05 -0.702307 0.00115197"/>
    <axis xyz="0 0 1"/>
    <limit effort="380" lower="-4.7139" upper="4.7139" velocity="9.43"/>
    <safety_controller k_position="100" k_velocity="2" soft_lower_limit="-3.05948851735" soft_upper_limit="3.05948851735"/>
    <dynamics damping="10.0" friction="4.5"/>
    <parent link="link2"/>
    <child link="link3"/>
  </joint>
  <link name="link4">
    <!-- link4 right_back_wheel -->
    <inertial>
      <mass value="4.90782352"/>
      <origin rpy="0 0 0" xyz="0.00000273   -0.02342897   -0.00561818"/>
      <inertia ixx="0.02108339" ixy="-0.00000071" ixz="-0.00000036" iyy="0.01108371" iyz="0.00064263" izz="0.02077348"/>
    </inertial>
    <visual>
      <origin rpy="0 0 0" xyz="0 0 0"/>
      <geometry>
        <mesh filename="package://mira_description/meshes/mira/Link4.stl"/>
      </geometry>
      <material name="blue"/>
    </visual>
    <collision>
      <origin rpy="0 0 0" xyz="0 0 0"/>
      <geometry>
        <mesh filename="package://mira_description/meshes/collision/Link4.stl"/>
      </geometry>
      <material name="blue"/>
    </collision>
  </link>
  <joint name="joint4" type="revolute">
    <!-- joint4 right_back_wheel_joint -->
    <origin rpy="-1.57108 0 0" xyz="0.000246029 -0.000361385 1.01006e-07"/>
    <axis xyz="0 0 1"/>
    <limit effort="70" lower="-2.61" upper="2.61" velocity="17.4"/>
    <safety_controller k_position="100" k_velocity="2" soft_lower_limit="-2.55948851735" soft_upper_limit="2.55948851735"/>
    <dynamics damping="2.5" friction="4.0"/>
    <parent link="link3"/>
    <child link="link4"/>
  </joint>
  <link name="link5">
    <!-- link5 left_leg -->
    <inertial>
      <mass value="5.89239887"/>
      <origin rpy="0 0 0" xyz="0.00003764   0.05360461   -0.27051890"/>
      <inertia ixx="0.34526601" ixy="-0.00001006" ixz="-0.00004889" iyy="0.33395748" iyz="-0.06425872" izz="0.02387784"/>
    </inertial>
    <visual>
      <origin rpy="0 0 0" xyz="0 0 0"/>
      <geometry>
        <mesh filename="package://mira_description/meshes/mira/Link5.stl"/>
      </geometry>
      <material name="white"/>
    </visual>
    <collision>
      <origin rpy="0 0 0" xyz="0 0 0"/>
      <geometry>
        <mesh filename="package://mira_description/meshes/collision/Link5.stl"/>
      </geometry>
      <material name="white"/>
      <!-- 
				<origin rpy="0 0 0" xyz="0 0 -0.23" />
				<geometry>
					<cylinder length="0.46" radius="0.115" />
				</geometry> -->
    </collision>
  </link>
  <joint name="joint5" type="revolute">
    <!-- joint5 base_to_left_leg -0.65 -->
    <origin rpy="-1.57208 -1.22465e-16 -3.14159" xyz="-0.000423097 -0.701012 -0.000901302"/>
    <axis xyz="0 0 1"/>
    <limit effort="80" lower="-4.7139" upper="4.7139" velocity="18.6"/>
    <safety_controller k_position="100" k_velocity="2" soft_lower_limit="-2.55948851735" soft_upper_limit="2.55948851735"/>
    <dynamics damping="5.0" friction="4.0"/>
    <parent link="link4"/>
    <child link="link5"/>
  </joint>
  <link name="link6">
    <!-- link6 left_base -->
    <inertial>
      <mass value="2.76974945"/>
      <origin rpy="0 0 0" xyz="0.00007333   0.01105196   0.02462915"/>
      <inertia ixx="0.00955946" ixy="-0.00001486" ixz="0.00000146" iyy="0.00723805" iyz="0.00066557" izz="0.00641809"/>
    </inertial>
    <visual>
      <origin rpy="0 0 0" xyz="0 0 0"/>
      <geometry>
        <mesh filename="package://mira_description/meshes/mira/Link6.stl"/>
      </geometry>
      <material name="blue"/>
    </visual>
    <collision>
      <origin rpy="0 0 0" xyz="0 0 0"/>
      <geometry>
        <mesh filename="package://mira_description/meshes/collision/Link6.stl"/>
      </geometry>
      <material name="blue"/>
    </collision>
  </link>
  <joint name="joint6" type="revolute">
    <!-- joint6 -->
    <origin rpy="-1.57066 0 0" xyz="-6.36962e-05 -0.000667725 -9.36304e-08"/>
    <axis xyz="0 0 1"/>
    <limit effort="21" lower="-4.7124" upper="4.7124" velocity="25.3"/>
    <safety_controller k_position="100" k_velocity="2" soft_lower_limit="-4.0" soft_upper_limit="4.0"/>
    <dynamics damping="1.25" friction="1.25"/>
    <parent link="link5"/>
    <child link="link6"/>
  </joint>
  <link name="link7">
    <inertial>
      <mass value="1.19341401"/>
      <origin rpy="0 0 0" xyz="-0.00006102   0.00027280   0.04324279"/>
      <inertia ixx="0.00254735" ixy="-0.00000278" ixz="-0.00000158" iyy="0.00255260" iyz="-0.00000991" izz="0.00099944"/>
    </inertial>
    <visual>
      <origin rpy="0 0 0" xyz="0 0 0"/>
      <geometry>
        <mesh filename="package://mira_description/meshes/mira/Link7.stl"/>
      </geometry>
    </visual>
    <collision>
      <origin rpy="0 0 0" xyz="0 0 0"/>
      <geometry>
        <mesh filename="package://mira_description/meshes/collision/Link7.stl"/>
      </geometry>
    </collision>
  </link>
  <joint name="joint7" type="revolute">
    <!-- joint7 -->
    <origin rpy="1.56449 0 0" xyz="9.93449e-05 0 0"/>
    <axis xyz="0 0 1"/>
    <limit effort="10" lower="-6.2832" upper="6.2832" velocity="10"/>
    <safety_controller k_position="10" k_velocity="1" soft_lower_limit="-4.0" soft_upper_limit="4.0"/>
    <dynamics damping="2" friction="2"/>
    <parent link="link6"/>
    <child link="link7"/>
  </joint>
  <link name="tool0"/>
  <joint name="link7_to_tool0" type="fixed">
    <!-- joint7 -->
    <origin rpy="0 0 0" xyz="0 0 0.10"/>
    <parent link="link7"/>
    <child link="tool0"/>
  </joint>
  <link name="flange"/>
  <joint name="link7_to_flange" type="fixed">
    <!-- joint7 -->
    <origin rpy="0 0 0" xyz="0 0 0.10"/>
    <parent link="link7"/>
    <child link="flange"/>
  </joint>
  <link name="ee_link"/>
  <joint name="flange_to_ee_link" type="fixed">
    <!-- joint7 -->
    <origin rpy="0 0 0" xyz="0 0 0.10"/>
    <parent link="link7"/>
    <child link="ee_link"/>
  </joint>
  <link name="world"/>
  <joint name="world_joint" type="fixed">
    <parent link="world"/>
    <child link="root_link"/>
    <origin rpy="0.0 0.0 0.0" xyz="0.0 0.0 0.0"/>
  </joint>
</robot>
